{"_default": {"1": {"app_name": "ap1",
    "health_check": true,
    "docker_image": "digitalocean/flask-helloworld", "dashboard_url": "/dashboard/ap1", "app_url": "http://ap1.hoster.local", "user_id": "admin"}}, "instances": {"1": {"provisioned": true, "provisioning": false, "docker_image": "digitalocean/flask-helloworld", "user_id": "admin", "machine_url": "http://192.168.196.125", "instance_url": "http://192.168.196.125:51127", "container_id": "a0a3f161f31831f023cc2e513c9fd0a44bad3a32f6c5f5a6594313d2f07c2cc8"}, "2": {"provisioned": false, "provisioning": false, "docker_image": "digitalocean/flask-helloworld", "user_id": "admin", "machine_url": "http://192.168.196.27", "error": "HTTPConnectionPool(host='192.168.196.27', port=8080): Max retries exceeded with url: /build-from-hub (Caused by NewConnectionError('<urllib3.connection.HTTPConnection object at 0x7fc834f8bbb0>: Failed to establish a new connection: [Errno 111] Connection refused'))"}, "3": {"provisioned": false, "provisioning": false, "docker_image": "digitalocean/flask-helloworld", "user_id": "admin", "machine_url": "http://192.168.196.27", "error": "HTTPConnectionPool(host='192.168.196.27', port=8080): Max retries exceeded with url: /build-from-hub (Caused by NewConnectionError('<urllib3.connection.HTTPConnection object at 0x7fc834f8bb80>: Failed to establish a new connection: [Errno 111] Connection refused'))"}, "4": {"provisioned": true, "provisioning": false, "docker_image": "digitalocean/flask-helloworld", "user_id": "admin", "machine_url": "http://192.168.196.125", "instance_url": "http://192.168.196.125:33147", "container_id": "a2bd589ff2180af8ab7b03f1b346fcc1795282f1a138ee32373dd089e2388256"}}}